Workbook

Sheet SUMMARY
B2: Dashboard
B5: =COUNTA('QA Log'!A2:A118) -> 117 | D5: Received | F5: =SUM('Data Collection_QQC'!BX3:BX118) -> 76 | H5: Approved | J5: =SUM('Data Collection_QQC'!BY3:BY118) -> 6 | L5: Rejected | N5: =B5-F5 -> 41 | P5: Remaining
D7: Forms that are completed! | H7: Forms that are approved! | L7: Forms that are rejected! | P7: Forms that are remaining!
B9: =IFERROR(__xludf.DUMMYFUNCTION("IFERROR(SPARKLINE(C11,{""charttype"",""bar"";""max"",1;""min"",0;""color1"",""#b6d7a8""}))"),"") | F9: =IFERROR(__xludf.DUMMYFUNCTION("IFERROR(SPARKLINE(G11,{""charttype"",""bar"";""max"",1;""min"",0;""color1"",""#b6d7a8""}))"),"") | J9: =IFERROR(__xludf.DUMMYFUNCTION("IFERROR(SPARKLINE(K11,{""charttype"",""bar"";""max"",1;""min"",0;""color1"",""#b6d7a8""}))"),"") | N9: =IFERROR(__xludf.DUMMYFUNCTION("IFERROR(SPARKLINE(O11,{""charttype"",""bar"";""max"",1;""min"",0;""color1"",""#b6d7a8""}))"),"")
B10: Target | C10: =SUM('Data Collection_QQC'!BV3:BV118) -> #NAME? | F10: Target | G10: =SUM('Data Collection_QQC'!BV3:BV118) -> #NAME? | J10: Target | K10: =SUM('Data Collection_QQC'!BV3:BV118) -> #NAME? | N10: Target | O10: =SUM('Data Collection_QQC'!BV3:BV118) -> #NAME?
B11: Percentage: | C11: =B5/C10 -> #NAME? | F11: Percentage: | G11: =F5/G10 -> #NAME? | J11: Percentage: | K11: =J5/K10 -> #NAME? | N11: Percentage: | O11: =N5/O10 -> #NAME?
B14: Province-wise Data
I16: Province | J16: Total Target | K16: Tota Received | L16: Tota Approved | M16: Total Rejected | N16: Total Remaining | O16: Visited HF | P16: Progress Indicator
I17: {=_xludf.UNIQUE('Data Collection_QQC'!B3:B118)} -> #NAME? | J17: =IF(I17<>"",SUMIF('Data Collection_QQC'!B3:B118,I17,'Data Collection_QQC'!BV3:BV118),"") -> #NAME? | K17: =IF(I17<>"",SUMIF('Data Collection_QQC'!B3:B118,I17,'Data Collection_QQC'!BW3:BW118),"") -> #NAME? | L17: =IF(I17<>"",SUMIF('Data Collection_QQC'!B3:B118,I17,'Data Collection_QQC'!BX3:BX118),"") -> #NAME? | M17: =IF(I17<>"",SUMIF('Data Collection_QQC'!B3:B118,I17,'Data Collection_QQC'!BY3:BY118),"") -> #NAME? | N17: =IF(I17<>"",SUMIF('Data Collection_QQC'!B3:B118,I17,'Data Collection_QQC'!BZ3:BZ118),"") -> #NAME? | O17: =IF(I17<>"",COUNTIF('Data Collection_QQC'!B3:B118,I17),"") -> #NAME? | P17: =IFERROR(__xludf.DUMMYFUNCTION("IF(I17<>"""",SPARKLINE(J17:N17, {""charttype"",""column""; ""color1"",""#2ECCD1""; ""color2"",""#FFB347""; ""max"",MAX($K$5:$N$13)}),"""") "),"")
I18: #NAME? | J18: =IF(I18<>"",SUMIF('Data Collection_QQC'!B4:B118,I18,'Data Collection_QQC'!BV4:BV118),"") -> #NAME? | K18: =IF(I18<>"",SUMIF('Data Collection_QQC'!B4:B118,I18,'Data Collection_QQC'!BW4:BW118),"") -> #NAME? | L18: =IF(I18<>"",SUMIF('Data Collection_QQC'!B4:B118,I18,'Data Collection_QQC'!BX4:BX118),"") -> #NAME? | M18: =IF(I18<>"",SUMIF('Data Collection_QQC'!B4:B118,I18,'Data Collection_QQC'!BY4:BY118),"") -> #NAME? | N18: =IF(I18<>"",SUMIF('Data Collection_QQC'!B4:B118,I18,'Data Collection_QQC'!BZ4:BZ118),"") -> #NAME? | O18: =IF(I18<>"",COUNTIF('Data Collection_QQC'!B4:B118,I18),"") -> #NAME? | P18: =IFERROR(__xludf.DUMMYFUNCTION("IF(I18<>"""",SPARKLINE(J18:N18, {""charttype"",""column""; ""color1"",""#2ECCD1""; ""color2"",""#FFB347""; ""max"",MAX($K$5:$N$13)}),"""") "),"")
I19: #NAME? | J19: =IF(I19<>"",SUMIF('Data Collection_QQC'!B5:B118,I19,'Data Collection_QQC'!BV5:BV118),"") -> #NAME? | K19: =IF(I19<>"",SUMIF('Data Collection_QQC'!B5:B118,I19,'Data Collection_QQC'!BW5:BW118),"") -> #NAME? | L19: =IF(I19<>"",SUMIF('Data Collection_QQC'!B5:B118,I19,'Data Collection_QQC'!BX5:BX118),"") -> #NAME? | M19: =IF(I19<>"",SUMIF('Data Collection_QQC'!B5:B118,I19,'Data Collection_QQC'!BY5:BY118),"") -> #NAME? | N19: =IF(I19<>"",SUMIF('Data Collection_QQC'!B5:B118,I19,'Data Collection_QQC'!BZ5:BZ118),"") -> #NAME? | O19: =IF(I19<>"",COUNTIF('Data Collection_QQC'!B5:B118,I19),"") -> #NAME? | P19: =IFERROR(__xludf.DUMMYFUNCTION("IF(I19<>"""",SPARKLINE(J19:N19, {""charttype"",""column""; ""color1"",""#2ECCD1""; ""color2"",""#FFB347""; ""max"",MAX($K$5:$N$13)}),"""") "),"")
I20: #NAME? | J20: =IF(I20<>"",SUMIF('Data Collection_QQC'!B6:B118,I20,'Data Collection_QQC'!BV6:BV118),"") -> #NAME? | K20: =IF(I20<>"",SUMIF('Data Collection_QQC'!B6:B118,I20,'Data Collection_QQC'!BW6:BW118),"") -> #NAME? | L20: =IF(I20<>"",SUMIF('Data Collection_QQC'!B6:B118,I20,'Data Collection_QQC'!BX6:BX118),"") -> #NAME? | M20: =IF(I20<>"",SUMIF('Data Collection_QQC'!B6:B118,I20,'Data Collection_QQC'!BY6:BY118),"") -> #NAME? | N20: =IF(I20<>"",SUMIF('Data Collection_QQC'!B6:B118,I20,'Data Collection_QQC'!BZ6:BZ118),"") -> #NAME? | O20: =IF(I20<>"",COUNTIF('Data Collection_QQC'!B6:B118,I20),"") -> #NAME? | P20: =IFERROR(__xludf.DUMMYFUNCTION("IF(I20<>"""",SPARKLINE(J20:N20, {""charttype"",""column""; ""color1"",""#2ECCD1""; ""color2"",""#FFB347""; ""max"",MAX($K$5:$N$13)}),"""") "),"")
I21: #NAME? | J21: =IF(I21<>"",SUMIF('Data Collection_QQC'!B7:B118,I21,'Data Collection_QQC'!BV7:BV118),"") -> #NAME? | K21: =IF(I21<>"",SUMIF('Data Collection_QQC'!B7:B118,I21,'Data Collection_QQC'!BW7:BW118),"") -> #NAME? | L21: =IF(I21<>"",SUMIF('Data Collection_QQC'!B7:B118,I21,'Data Collection_QQC'!BX7:BX118),"") -> #NAME? | M21: =IF(I21<>"",SUMIF('Data Collection_QQC'!B7:B118,I21,'Data Collection_QQC'!BY7:BY118),"") -> #NAME? | N21: =IF(I21<>"",SUMIF('Data Collection_QQC'!B7:B118,I21,'Data Collection_QQC'!BZ7:BZ118),"") -> #NAME? | O21: =IF(I21<>"",COUNTIF('Data Collection_QQC'!B7:B118,I21),"") -> #NAME? | P21: =IFERROR(__xludf.DUMMYFUNCTION("IF(I21<>"""",SPARKLINE(J21:N21, {""charttype"",""column""; ""color1"",""#2ECCD1""; ""color2"",""#FFB347""; ""max"",MAX($K$5:$N$13)}),"""") "),"")
I22: #NAME? | J22: =IF(I22<>"",SUMIF('Data Collection_QQC'!B8:B118,I22,'Data Collection_QQC'!BV8:BV118),"") -> #NAME? | K22: =IF(I22<>"",SUMIF('Data Collection_QQC'!B8:B118,I22,'Data Collection_QQC'!BW8:BW118),"") -> #NAME? | L22: =IF(I22<>"",SUMIF('Data Collection_QQC'!B8:B118,I22,'Data Collection_QQC'!BX8:BX118),"") -> #NAME? | M22: =IF(I22<>"",SUMIF('Data Collection_QQC'!B8:B118,I22,'Data Collection_QQC'!BY8:BY118),"") -> #NAME? | N22: =IF(I22<>"",SUMIF('Data Collection_QQC'!B8:B118,I22,'Data Collection_QQC'!BZ8:BZ118),"") -> #NAME? | O22: =IF(I22<>"",COUNTIF('Data Collection_QQC'!B8:B118,I22),"") -> #NAME? | P22: =IFERROR(__xludf.DUMMYFUNCTION("IF(I22<>"""",SPARKLINE(J22:N22, {""charttype"",""column""; ""color1"",""#2ECCD1""; ""color2"",""#FFB347""; ""max"",MAX($K$5:$N$13)}),"""") "),"")
I23: #NAME? | J23: =IF(I23<>"",SUMIF('Data Collection_QQC'!B9:B118,I23,'Data Collection_QQC'!BV9:BV118),"") -> #NAME? | K23: =IF(I23<>"",SUMIF('Data Collection_QQC'!B9:B118,I23,'Data Collection_QQC'!BW9:BW118),"") -> #NAME? | L23: =IF(I23<>"",SUMIF('Data Collection_QQC'!B9:B118,I23,'Data Collection_QQC'!BX9:BX118),"") -> #NAME? | M23: =IF(I23<>"",SUMIF('Data Collection_QQC'!B9:B118,I23,'Data Collection_QQC'!BY9:BY118),"") -> #NAME? | N23: =IF(I23<>"",SUMIF('Data Collection_QQC'!B9:B118,I23,'Data Collection_QQC'!BZ9:BZ118),"") -> #NAME? | O23: =IF(I23<>"",COUNTIF('Data Collection_QQC'!B9:B118,I23),"") -> #NAME? | P23: =IFERROR(__xludf.DUMMYFUNCTION("IF(I23<>"""",SPARKLINE(J23:N23, {""charttype"",""column""; ""color1"",""#2ECCD1""; ""color2"",""#FFB347""; ""max"",MAX($K$5:$N$13)}),"""") "),"")
I24: #NAME? | J24: =IF(I24<>"",SUMIF('Data Collection_QQC'!B10:B118,I24,'Data Collection_QQC'!BV10:BV118),"") -> #NAME? | K24: =IF(I24<>"",SUMIF('Data Collection_QQC'!B10:B118,I24,'Data Collection_QQC'!BW10:BW118),"") -> #NAME? | L24: =IF(I24<>"",SUMIF('Data Collection_QQC'!B10:B118,I24,'Data Collection_QQC'!BX10:BX118),"") -> #NAME? | M24: =IF(I24<>"",SUMIF('Data Collection_QQC'!B10:B118,I24,'Data Collection_QQC'!BY10:BY118),"") -> #NAME? | N24: =IF(I24<>"",SUMIF('Data Collection_QQC'!B10:B118,I24,'Data Collection_QQC'!BZ10:BZ118),"") -> #NAME? | O24: =IF(I24<>"",COUNTIF('Data Collection_QQC'!B10:B118,I24),"") -> #NAME? | P24: =IFERROR(__xludf.DUMMYFUNCTION("IF(I24<>"""",SPARKLINE(J24:N24, {""charttype"",""column""; ""color1"",""#2ECCD1""; ""color2"",""#FFB347""; ""max"",MAX($K$5:$N$13)}),"""") "),"")
I25: #NAME? | J25: =IF(I25<>"",SUMIF('Data Collection_QQC'!B11:B118,I25,'Data Collection_QQC'!BV11:BV118),"") -> #NAME? | K25: =IF(I25<>"",SUMIF('Data Collection_QQC'!B11:B118,I25,'Data Collection_QQC'!BW11:BW118),"") -> #NAME? | L25: =IF(I25<>"",SUMIF('Data Collection_QQC'!B11:B118,I25,'Data Collection_QQC'!BX11:BX118),"") -> #NAME? | M25: =IF(I25<>"",SUMIF('Data Collection_QQC'!B11:B118,I25,'Data Collection_QQC'!BY11:BY118),"") -> #NAME? | N25: =IF(I25<>"",SUMIF('Data Collection_QQC'!B11:B118,I25,'Data Collection_QQC'!BZ11:BZ118),"") -> #NAME? | O25: =IF(I25<>"",COUNTIF('Data Collection_QQC'!B11:B118,I25),"") -> #NAME? | P25: =IFERROR(__xludf.DUMMYFUNCTION("IF(I25<>"""",SPARKLINE(J25:N25, {""charttype"",""column""; ""color1"",""#2ECCD1""; ""color2"",""#FFB347""; ""max"",MAX($K$5:$N$13)}),"""") "),"")
I26: #NAME? | J26: =IF(I26<>"",SUMIF('Data Collection_QQC'!B12:B118,I26,'Data Collection_QQC'!BV12:BV118),"") -> #NAME? | K26: =IF(I26<>"",SUMIF('Data Collection_QQC'!B12:B118,I26,'Data Collection_QQC'!BW12:BW118),"") -> #NAME? | L26: =IF(I26<>"",SUMIF('Data Collection_QQC'!B12:B118,I26,'Data Collection_QQC'!BX12:BX118),"") -> #NAME? | M26: =IF(I26<>"",SUMIF('Data Collection_QQC'!B12:B118,I26,'Data Collection_QQC'!BY12:BY118),"") -> #NAME? | N26: =IF(I26<>"",SUMIF('Data Collection_QQC'!B12:B118,I26,'Data Collection_QQC'!BZ12:BZ118),"") -> #NAME? | O26: =IF(I26<>"",COUNTIF('Data Collection_QQC'!B12:B118,I26),"") -> #NAME? | P26: =IFERROR(__xludf.DUMMYFUNCTION("IF(I26<>"""",SPARKLINE(J26:N26, {""charttype"",""column""; ""color1"",""#2ECCD1""; ""color2"",""#FFB347""; ""max"",MAX($K$5:$N$13)}),"""") "),"")
I27: #NAME? | J27: =IF(I27<>"",SUMIF('Data Collection_QQC'!B13:B118,I27,'Data Collection_QQC'!BV13:BV118),"") -> #NAME? | K27: =IF(I27<>"",SUMIF('Data Collection_QQC'!B13:B118,I27,'Data Collection_QQC'!BW13:BW118),"") -> #NAME? | L27: =IF(I27<>"",SUMIF('Data Collection_QQC'!B13:B118,I27,'Data Collection_QQC'!BX13:BX118),"") -> #NAME? | M27: =IF(I27<>"",SUMIF('Data Collection_QQC'!B13:B118,I27,'Data Collection_QQC'!BY13:BY118),"") -> #NAME? | N27: =IF(I27<>"",SUMIF('Data Collection_QQC'!B13:B118,I27,'Data Collection_QQC'!BZ13:BZ118),"") -> #NAME? | O27: =IF(I27<>"",COUNTIF('Data Collection_QQC'!B13:B118,I27),"") -> #NAME? | P27: =IFERROR(__xludf.DUMMYFUNCTION("IF(I27<>"""",SPARKLINE(J27:N27, {""charttype"",""column""; ""color1"",""#2ECCD1""; ""color2"",""#FFB347""; ""max"",MAX($K$5:$N$13)}),"""") "),"")
I28: #NAME? | J28: =IF(I28<>"",SUMIF('Data Collection_QQC'!B14:B118,I28,'Data Collection_QQC'!BV14:BV118),"") -> #NAME? | K28: =IF(I28<>"",SUMIF('Data Collection_QQC'!B14:B118,I28,'Data Collection_QQC'!BW14:BW118),"") -> #NAME? | L28: =IF(I28<>"",SUMIF('Data Collection_QQC'!B14:B118,I28,'Data Collection_QQC'!BX14:BX118),"") -> #NAME? | M28: =IF(I28<>"",SUMIF('Data Collection_QQC'!B14:B118,I28,'Data Collection_QQC'!BY14:BY118),"") -> #NAME? | N28: =IF(I28<>"",SUMIF('Data Collection_QQC'!B14:B118,I28,'Data Collection_QQC'!BZ14:BZ118),"") -> #NAME? | O28: =IF(I28<>"",COUNTIF('Data Collection_QQC'!B14:B118,I28),"") -> #NAME? | P28: =IFERROR(__xludf.DUMMYFUNCTION("IF(I28<>"""",SPARKLINE(J28:N28, {""charttype"",""column""; ""color1"",""#2ECCD1""; ""color2"",""#FFB347""; ""max"",MAX($K$5:$N$13)}),"""") "),"")
I29: #NAME? | J29: =IF(I29<>"",SUMIF('Data Collection_QQC'!B15:B118,I29,'Data Collection_QQC'!BV15:BV118),"") -> #NAME? | K29: =IF(I29<>"",SUMIF('Data Collection_QQC'!B15:B118,I29,'Data Collection_QQC'!BW15:BW118),"") -> #NAME? | L29: =IF(I29<>"",SUMIF('Data Collection_QQC'!B15:B118,I29,'Data Collection_QQC'!BX15:BX118),"") -> #NAME? | M29: =IF(I29<>"",SUMIF('Data Collection_QQC'!B15:B118,I29,'Data Collection_QQC'!BY15:BY118),"") -> #NAME? | N29: =IF(I29<>"",SUMIF('Data Collection_QQC'!B15:B118,I29,'Data Collection_QQC'!BZ15:BZ118),"") -> #NAME? | O29: =IF(I29<>"",COUNTIF('Data Collection_QQC'!B15:B118,I29),"") -> #NAME? | P29: =IFERROR(__xludf.DUMMYFUNCTION("IF(I29<>"""",SPARKLINE(J29:N29, {""charttype"",""column""; ""color1"",""#2ECCD1""; ""color2"",""#FFB347""; ""max"",MAX($K$5:$N$13)}),"""") "),"")
I30: #NAME? | J30: =IF(I30<>"",SUMIF('Data Collection_QQC'!B16:B118,I30,'Data Collection_QQC'!BV16:BV118),"") -> #NAME? | K30: =IF(I30<>"",SUMIF('Data Collection_QQC'!B16:B118,I30,'Data Collection_QQC'!BW16:BW118),"") -> #NAME? | L30: =IF(I30<>"",SUMIF('Data Collection_QQC'!B16:B118,I30,'Data Collection_QQC'!BX16:BX118),"") -> #NAME? | M30: =IF(I30<>"",SUMIF('Data Collection_QQC'!B16:B118,I30,'Data Collection_QQC'!BY16:BY118),"") -> #NAME? | N30: =IF(I30<>"",SUMIF('Data Collection_QQC'!B16:B118,I30,'Data Collection_QQC'!BZ16:BZ118),"") -> #NAME? | O30: =IF(I30<>"",COUNTIF('Data Collection_QQC'!B16:B118,I30),"") -> #NAME? | P30: =IFERROR(__xludf.DUMMYFUNCTION("IF(I30<>"""",SPARKLINE(J30:N30, {""charttype"",""column""; ""color1"",""#2ECCD1""; ""color2"",""#FFB347""; ""max"",MAX($K$5:$N$13)}),"""") "),"")
I31: #NAME? | J31: =IF(I31<>"",SUMIF('Data Collection_QQC'!B17:B118,I31,'Data Collection_QQC'!BV17:BV118),"") -> #NAME? | K31: =IF(I31<>"",SUMIF('Data Collection_QQC'!B17:B118,I31,'Data Collection_QQC'!BW17:BW118),"") -> #NAME? | L31: =IF(I31<>"",SUMIF('Data Collection_QQC'!B17:B118,I31,'Data Collection_QQC'!BX17:BX118),"") -> #NAME? | M31: =IF(I31<>"",SUMIF('Data Collection_QQC'!B17:B118,I31,'Data Collection_QQC'!BY17:BY118),"") -> #NAME? | N31: =IF(I31<>"",SUMIF('Data Collection_QQC'!B17:B118,I31,'Data Collection_QQC'!BZ17:BZ118),"") -> #NAME? | O31: =IF(I31<>"",COUNTIF('Data Collection_QQC'!B17:B118,I31),"") -> #NAME? | P31: =IFERROR(__xludf.DUMMYFUNCTION("IF(I31<>"""",SPARKLINE(J31:N31, {""charttype"",""column""; ""color1"",""#2ECCD1""; ""color2"",""#FFB347""; ""max"",MAX($K$5:$N$13)}),"""") "),"")
I32: #NAME? | J32: =IF(I32<>"",SUMIF('Data Collection_QQC'!B18:B118,I32,'Data Collection_QQC'!BV18:BV118),"") -> #NAME? | K32: =IF(I32<>"",SUMIF('Data Collection_QQC'!B18:B118,I32,'Data Collection_QQC'!BW18:BW118),"") -> #NAME? | L32: =IF(I32<>"",SUMIF('Data Collection_QQC'!B18:B118,I32,'Data Collection_QQC'!BX18:BX118),"") -> #NAME? | M32: =IF(I32<>"",SUMIF('Data Collection_QQC'!B18:B118,I32,'Data Collection_QQC'!BY18:BY118),"") -> #NAME? | N32: =IF(I32<>"",SUMIF('Data Collection_QQC'!B18:B118,I32,'Data Collection_QQC'!BZ18:BZ118),"") -> #NAME? | O32: =IF(I32<>"",COUNTIF('Data Collection_QQC'!B18:B118,I32),"") -> #NAME? | P32: =IFERROR(__xludf.DUMMYFUNCTION("IF(I32<>"""",SPARKLINE(J32:N32, {""charttype"",""column""; ""color1"",""#2ECCD1""; ""color2"",""#FFB347""; ""max"",MAX($K$5:$N$13)}),"""") "),"")
I33: #NAME? | J33: =IF(I33<>"",SUMIF('Data Collection_QQC'!B19:B118,I33,'Data Collection_QQC'!BV19:BV118),"") -> #NAME? | K33: =IF(I33<>"",SUMIF('Data Collection_QQC'!B19:B118,I33,'Data Collection_QQC'!BW19:BW118),"") -> #NAME? | L33: =IF(I33<>"",SUMIF('Data Collection_QQC'!B19:B118,I33,'Data Collection_QQC'!BX19:BX118),"") -> #NAME? | M33: =IF(I33<>"",SUMIF('Data Collection_QQC'!B19:B118,I33,'Data Collection_QQC'!BY19:BY118),"") -> #NAME? | N33: =IF(I33<>"",SUMIF('Data Collection_QQC'!B19:B118,I33,'Data Collection_QQC'!BZ19:BZ118),"") -> #NAME? | O33: =IF(I33<>"",COUNTIF('Data Collection_QQC'!B19:B118,I33),"") -> #NAME? | P33: =IFERROR(__xludf.DUMMYFUNCTION("IF(I33<>"""",SPARKLINE(J33:N33, {""charttype"",""column""; ""color1"",""#2ECCD1""; ""color2"",""#FFB347""; ""max"",MAX($K$5:$N$13)}),"""") "),"")
I34: #NAME? | J34: =IF(I34<>"",SUMIF('Data Collection_QQC'!B20:B118,I34,'Data Collection_QQC'!BV20:BV118),"") -> #NAME? | K34: =IF(I34<>"",SUMIF('Data Collection_QQC'!B20:B118,I34,'Data Collection_QQC'!BW20:BW118),"") -> #NAME? | L34: =IF(I34<>"",SUMIF('Data Collection_QQC'!B20:B118,I34,'Data Collection_QQC'!BX20:BX118),"") -> #NAME? | M34: =IF(I34<>"",SUMIF('Data Collection_QQC'!B20:B118,I34,'Data Collection_QQC'!BY20:BY118),"") -> #NAME? | N34: =IF(I34<>"",SUMIF('Data Collection_QQC'!B20:B118,I34,'Data Collection_QQC'!BZ20:BZ118),"") -> #NAME? | O34: =IF(I34<>"",COUNTIF('Data Collection_QQC'!B20:B118,I34),"") -> #NAME? | P34: =IFERROR(__xludf.DUMMYFUNCTION("IF(I34<>"""",SPARKLINE(J34:N34, {""charttype"",""column""; ""color1"",""#2ECCD1""; ""color2"",""#FFB347""; ""max"",MAX($K$5:$N$13)}),"""") "),"")
I35: #NAME? | J35: =IF(I35<>"",SUMIF('Data Collection_QQC'!B21:B118,I35,'Data Collection_QQC'!BV21:BV118),"") -> #NAME? | K35: =IF(I35<>"",SUMIF('Data Collection_QQC'!B21:B118,I35,'Data Collection_QQC'!BW21:BW118),"") -> #NAME? | L35: =IF(I35<>"",SUMIF('Data Collection_QQC'!B21:B118,I35,'Data Collection_QQC'!BX21:BX118),"") -> #NAME? | M35: =IF(I35<>"",SUMIF('Data Collection_QQC'!B21:B118,I35,'Data Collection_QQC'!BY21:BY118),"") -> #NAME? | N35: =IF(I35<>"",SUMIF('Data Collection_QQC'!B21:B118,I35,'Data Collection_QQC'!BZ21:BZ118),"") -> #NAME? | O35: =IF(I35<>"",COUNTIF('Data Collection_QQC'!B21:B118,I35),"") -> #NAME? | P35: =IFERROR(__xludf.DUMMYFUNCTION("IF(I35<>"""",SPARKLINE(J35:N35, {""charttype"",""column""; ""color1"",""#2ECCD1""; ""color2"",""#FFB347""; ""max"",MAX($K$5:$N$13)}),"""") "),"")
J36: =IF(I36<>"",SUMIF('Data Collection_QQC'!B22:B118,I36,'Data Collection_QQC'!BV22:BV118),"") | K36: =IF(I36<>"",SUMIF('Data Collection_QQC'!B22:B118,I36,'Data Collection_QQC'!BW22:BW118),"") | L36: =IF(I36<>"",SUMIF('Data Collection_QQC'!B22:B118,I36,'Data Collection_QQC'!BX22:BX118),"") | M36: =IF(I36<>"",SUMIF('Data Collection_QQC'!B22:B118,I36,'Data Collection_QQC'!BY22:BY118),"") | N36: =IF(I36<>"",SUMIF('Data Collection_QQC'!B22:B118,I36,'Data Collection_QQC'!BZ22:BZ118),"") | O36: =IF(I36<>"",COUNTIF('Data Collection_QQC'!B22:B118,I36),"") | P36: =IFERROR(__xludf.DUMMYFUNCTION("IF(I36<>"""",SPARKLINE(J36:N36, {""charttype"",""column""; ""color1"",""#2ECCD1""; ""color2"",""#FFB347""; ""max"",MAX($K$5:$N$13)}),"""") "),"")
J37: =IF(I37<>"",SUMIF('Data Collection_QQC'!B23:B118,I37,'Data Collection_QQC'!BV23:BV118),"") | K37: =IF(I37<>"",SUMIF('Data Collection_QQC'!B23:B118,I37,'Data Collection_QQC'!BW23:BW118),"") | L37: =IF(I37<>"",SUMIF('Data Collection_QQC'!B23:B118,I37,'Data Collection_QQC'!BX23:BX118),"") | M37: =IF(I37<>"",SUMIF('Data Collection_QQC'!B23:B118,I37,'Data Collection_QQC'!BY23:BY118),"") | N37: =IF(I37<>"",SUMIF('Data Collection_QQC'!B23:B118,I37,'Data Collection_QQC'!BZ23:BZ118),"") | O37: =IF(I37<>"",COUNTIF('Data Collection_QQC'!B23:B118,I37),"") | P37: =IFERROR(__xludf.DUMMYFUNCTION("IF(I37<>"""",SPARKLINE(J37:N37, {""charttype"",""column""; ""color1"",""#2ECCD1""; ""color2"",""#FFB347""; ""max"",MAX($K$5:$N$13)}),"""") "),"")
J38: =IF(I38<>"",SUMIF('Data Collection_QQC'!B24:B118,I38,'Data Collection_QQC'!BV24:BV118),"") | K38: =IF(I38<>"",SUMIF('Data Collection_QQC'!B24:B118,I38,'Data Collection_QQC'!BW24:BW118),"") | L38: =IF(I38<>"",SUMIF('Data Collection_QQC'!B24:B118,I38,'Data Collection_QQC'!BX24:BX118),"") | M38: =IF(I38<>"",SUMIF('Data Collection_QQC'!B24:B118,I38,'Data Collection_QQC'!BY24:BY118),"") | N38: =IF(I38<>"",SUMIF('Data Collection_QQC'!B24:B118,I38,'Data Collection_QQC'!BZ24:BZ118),"") | O38: =IF(I38<>"",COUNTIF('Data Collection_QQC'!B24:B118,I38),"") | P38: =IFERROR(__xludf.DUMMYFUNCTION("IF(I38<>"""",SPARKLINE(J38:N38, {""charttype"",""column""; ""color1"",""#2ECCD1""; ""color2"",""#FFB347""; ""max"",MAX($K$5:$N$13)}),"""") "),"")
J39: =IF(I39<>"",SUMIF('Data Collection_QQC'!B25:B118,I39,'Data Collection_QQC'!BV25:BV118),"") | K39: =IF(I39<>"",SUMIF('Data Collection_QQC'!B25:B118,I39,'Data Collection_QQC'!BW25:BW118),"") | L39: =IF(I39<>"",SUMIF('Data Collection_QQC'!B25:B118,I39,'Data Collection_QQC'!BX25:BX118),"") | M39: =IF(I39<>"",SUMIF('Data Collection_QQC'!B25:B118,I39,'Data Collection_QQC'!BY25:BY118),"") | N39: =IF(I39<>"",SUMIF('Data Collection_QQC'!B25:B118,I39,'Data Collection_QQC'!BZ25:BZ118),"") | O39: =IF(I39<>"",COUNTIF('Data Collection_QQC'!B25:B118,I39),"") | P39: =IFERROR(__xludf.DUMMYFUNCTION("IF(I39<>"""",SPARKLINE(J39:N39, {""charttype"",""column""; ""color1"",""#2ECCD1""; ""color2"",""#FFB347""; ""max"",MAX($K$5:$N$13)}),"""") "),"")
J40: =IF(I40<>"",SUMIF('Data Collection_QQC'!B26:B118,I40,'Data Collection_QQC'!BV26:BV118),"") | K40: =IF(I40<>"",SUMIF('Data Collection_QQC'!B26:B118,I40,'Data Collection_QQC'!BW26:BW118),"") | L40: =IF(I40<>"",SUMIF('Data Collection_QQC'!B26:B118,I40,'Data Collection_QQC'!BX26:BX118),"") | M40: =IF(I40<>"",SUMIF('Data Collection_QQC'!B26:B118,I40,'Data Collection_QQC'!BY26:BY118),"") | N40: =IF(I40<>"",SUMIF('Data Collection_QQC'!B26:B118,I40,'Data Collection_QQC'!BZ26:BZ118),"") | O40: =IF(I40<>"",COUNTIF('Data Collection_QQC'!B26:B118,I40),"") | P40: =IFERROR(__xludf.DUMMYFUNCTION("IF(I40<>"""",SPARKLINE(K40:N40, {""charttype"",""column""; ""color1"",""#2ECCD1""; ""color2"",""#FFB347""; ""max"",MAX($K$5:$N$13)}),"""") "),"")
B42: Tool-wise Summary
C45: QQC | J45: HF Level Data Verification
F47: =COUNTIF('QA Log'!M:M,"QQC") -> 30 | G47: Received | M47: =COUNTIF('QA Log'!M:M,"Data Verification") -> 88 | N47: Received
F48: =COUNTIFS('QA Log'!M:M,"QQC",'QA Log'!Z:Z,"Approved") -> 16 | G48: Approved | M48: =COUNTIFS('QA Log'!M:M,"Data Verification",'QA Log'!Z:Z,"Approved") -> 28 | N48: Approved
F49: =COUNTIFS('QA Log'!M:M,"QQC",'QA Log'!Z:Z,"Rejected") -> 0 | G49: Rejected | M49: =COUNTIFS('QA Log'!M:M,"Data Verification",'QA Log'!Z:Z,"Rejected") -> 4 | N49: Rejected
F50: =F47-F48 -> 14 | G50: Remaining | M50: =M47-M48 -> 60 | N50: Remaining
C53: Vignette
F55: =COUNTIF('QA Log'!M:M,"Vignette") -> 149 | G55: Received
...

Sheet Data Collection_QQC
E1: Data Collection Progress Sheet | Q1: Male<< | R1: QQC (Structural Indicators) | V1: >>Female | AG1: Male<< | AK1: HF Level Data Verification | AO1: >>Female | AY1: Vignette [1:4] | BH1: Vignette [5:10] | BQ1: Vignette [Exit Interview] | BV1: Total Data Tracking | CA1: Data Collection Progress by Tool Type _ Received | CD1: Data Collection Progress by Tool Type _ Approved | CG1: Final Status
A2: =IFERROR(__xludf.DUMMYFUNCTION("UNIQUE(FILTER('QA Log'!D:D, 'QA Log'!AA:AA<>""Fake/Test data"", 'QA Log'!D:D<>""""))"),"Site Visit ID") -> Site Visit ID | B2: Province | C2: District | D2: HF Type | E2: HF Name | F2: DC Status | G2: DC Start Date | H2: DC End Date | I2: Target | J2: Received | K2: Approved >> | L2: 1. General Management | M2: 3. Curative Consultation (OPD) | N2: 5. Laboratory | O2: 6. Essential Medicine Management | P2: 7. Tracer Medicine | Q2: 11. Additional Questions | R2: Rejected | S2: Remaining | T2: Target | U2: Received | V2: Approved>> | W2: 8. Maternity | X2: 9. EPI and Pre-school Consultation | Y2: 10. Antenatal Care (ANC) | Z2: 2. Hygiene and Sterilization | AA2: 4. Family Planning | AB2: Rejected | AC2: Remaining | AD2: Target | AE2: Received | AF2: Approved | AG2: Medicine (section 2) | AH2: Lab Testing Availability | AI2: Other than P4P (section 6) | AJ2: Hospital Governance | AK2: Rejected | AL2: Remaining | AM2: Target | AN2: Received | AO2: Approved | AP2: Personnel (section 1) | AQ2: Consumable (section 3) | AR2: Equipments (section 4) | AS2: Rejected | AT2: Remaining | AU2: Target | AV2: Received | AW2: Approved | AX2: Vignette [1] | AY2: Vignette [2] | AZ2: Vignette [3] | BA2: Vignette [4] | BB2: Rejected | BC2: Remaining | BD2: Target | BE2: Received | BF2: Approved | BG2: Vignette [5] | BH2: Vignette [6] | BI2: Vignette [7] | BJ2: Vignette [8] | BK2: Vignette [9] | BL2: Vignette [10] | BM2: Rejected | BN2: Remaining | BO2: Target | BP2: Received | BQ2: Approved | BR2: [Exit Interview 1] | BS2: [Exit Interview 2] | BT2: Rejected | BU2: Remaining | BV2: Target | BW2: Received | BX2: Approved | BY2: Rejected | BZ2: Remaining | CA2: QQC (Structural Indicators) | CB2: HF Level Data Verification | CC2: Vignette | CD2: QQC (Structural Indicators) | CE2: HF Level Data Verification | CF2: Vignette | CG2: DC Status | CH2: Remarks
A3: =IFERROR(__xludf.DUMMYFUNCTION("""COMPUTED_VALUE"""),"HER-JZJ-HF4362-Q2-2025-1097-01") -> HER-JZJ-HF4362-Q2-2025-1097-01 | B3: {=_xludf.XLOOKUP(A3,'QA Log'!D:D,'QA Log'!E:E,"")} -> #NAME? | C3: {=_xludf.XLOOKUP(A3,'QA Log'!D:D,'QA Log'!F:F,"")} -> #NAME? | D3: {=_xludf.XLOOKUP(A3,'QA Log'!D:D,'QA Log'!H:H,"")} -> #NAME? | E3: {=_xludf.XLOOKUP(A3,'QA Log'!D:D,'QA Log'!G:G,"")} -> #NAME? | F3: Completed | G3: 45959 | H3: 45960 | I3: =IF(A3="", "", IF(OR(D3="RH", D3="PH", D3="SHC"), 0, IF(D3="BHC", 5, 6))) -> #NAME? | J3: =IF(A3="","",SUM( COUNTIFS('QA Log'!D:D,A3,'QA Log'!M:M,"QQC",'QA Log'!L:L,"*1. General Management*"), COUNTIFS('QA Log'!D:D,A3,'QA Log'!M:M,"QQC",'QA Log'!L:L,"*3. Curative Consultation (OPD)*"), COUNTIFS('QA Log'!D:D,A3,'QA Log'!M:M,"QQC",'QA Log'!L:L,"*5. Laboratory*"), COUNTIFS('QA Log'!D:D,A3,'QA Log'!M:M,"QQC",'QA Log'!L:L,"*6. Essential Medicine Management*"), COUNTIFS('QA Log'!D:D,A3,'QA Log'!M:M,"QQC",'QA Log'!L:L,"*7. Tracer Medicine*"), COUNTIFS('QA Log'!D:D,A3,'QA Log'!M:M,"QQC",'QA Log'!L:L,"*11. Additional Questions*"))) -> 0 | K3: =IF(A3="","",SUM( COUNTIFS('QA Log'!D:D,A3,'QA Log'!M:M,"QQC",'QA Log'!Z:Z,"Approved",'QA Log'!L:L,"*1. General Management*"), COUNTIFS('QA Log'!D:D,A3,'QA Log'!M:M,"QQC",'QA Log'!Z:Z,"Approved",'QA Log'!L:L,"*3. Curative Consultation (OPD)*"), COUNTIFS('QA Log'!D:D,A3,'QA Log'!M:M,"QQC",'QA Log'!Z:Z,"Approved",'QA Log'!L:L,"*5. Laboratory*"), COUNTIFS('QA Log'!D:D,A3,'QA Log'!M:M,"QQC",'QA Log'!Z:Z,"Approved",'QA Log'!L:L,"*6. Essential Medicine Management*"), COUNTIFS('QA Log'!D:D,A3,'QA Log'!M:M,"QQC",'QA Log'!Z:Z,"Approved",'QA Log'!L:L,"*7. Tracer Medicine*"), COUNTIFS('QA Log'!D:D,A3,'QA Log'!M:M,"QQC",'QA Log'!Z:Z,"Approved",'QA Log'!L:L,"*11. Additional Questions*"))) -> 0 | L3: =IF(A3<>"",COUNTIFS('QA Log'!D:D,A3,'QA Log'!M:M,"QQC",'QA Log'!L:L,"1. General Management",'QA Log'!Z:Z,"Approved"),"") -> 0 | M3: =IF(A3<>"",COUNTIFS('QA Log'!D:D,A3,'QA Log'!M:M,"QQC",'QA Log'!L:L,"3. Curative Consultation (OPD)",'QA Log'!Z:Z,"Approved"),"") -> 0 | N3: =IF(A3<>"",COUNTIFS('QA Log'!D:D,A3,'QA Log'!M:M,"QQC",'QA Log'!L:L,"5. Laboratory",'QA Log'!Z:Z,"Approved"),"") -> 0 | O3: =IF(A3<>"",COUNTIFS('QA Log'!D:D,A3,'QA Log'!M:M,"QQC",'QA Log'!L:L,"6. Essential Medicine Management",'QA Log'!Z:Z,"Approved"),"") -> 0 | P3: =IF(A3<>"",COUNTIFS('QA Log'!D:D,A3,'QA Log'!M:M,"QQC",'QA Log'!L:L,"7. Tracer Medicine",'QA Log'!Z:Z,"Approved"),"") -> 0 | Q3: =IF(A3<>"",COUNTIFS('QA Log'!D:D,A3,'QA Log'!M:M,"QQC",'QA Log'!L:L,"11. Additional Questions",'QA Log'!Z:Z,"Approved"),"") -> 0 | R3: =IF(A3="","",SUM( COUNTIFS('QA Log'!D:D,A3,'QA Log'!M:M,"QQC",'QA Log'!Z:Z,"Rejected",'QA Log'!L:L,"*8. Maternity*"), COUNTIFS('QA Log'!D:D,A3,'QA Log'!M:M,"QQC",'QA Log'!Z:Z,"Rejected",'QA Log'!L:L,"*EPI*"), COUNTIFS('QA Log'!D:D,A3,'QA Log'!M:M,"QQC",'QA Log'!Z:Z,"Rejected",'QA Log'!L:L,"*10. Antenatal Care (ANC)*"), COUNTIFS('QA Log'!D:D,A3,'QA Log'!M:M,"QQC",'QA Log'!Z:Z,"Rejected",'QA Log'!L:L,"*2. Hygiene and Sterilization*"), COUNTIFS('QA Log'!D:D,A3,'QA Log'!M:M,"QQC",'QA Log'!Z:Z,"Rejected",'QA Log'!L:L,"*Family Planning*"))) -> 0 | S3: =IF(A3<>"",I3-K3,"") -> #NAME? | T3: =IF(A3="", "", IF(OR(D3="RH", D3="PH", D3="SHC"), 0, IF(D3="BHC", 5, 5))) -> #NAME? | U3: =IF(A3="","", SUM( COUNTIFS('QA Log'!D:D,A3,'QA Log'!M:M,"QQC",'QA Log'!L:L,"*8. Maternity*"), COUNTIFS('QA Log'!D:D,A3,'QA Log'!M:M,"QQC",'QA Log'!L:L,"*9. EPI and Pre-school Consultation*"), COUNTIFS('QA Log'!D:D,A3,'QA Log'!M:M,"QQC",'QA Log'!L:L,"*10. Antenatal Care (ANC)*"), COUNTIFS('QA Log'!D:D,A3,'QA Log'!M:M,"QQC",'QA Log'!L:L,"*2. Hygiene and Sterilization*"), COUNTIFS('QA Log'!D:D,A3,'QA Log'!M:M,"QQC",'QA Log'!L:L,"*4. Family Planning*") )) -> 0 | V3: =IF(A3="","", SUM( COUNTIFS('QA Log'!D:D,A3,'QA Log'!M:M,"QQC",'QA Log'!Z:Z,"Approved",'QA Log'!L:L,"*8. Maternity*"), COUNTIFS('QA Log'!D:D,A3,'QA Log'!M:M,"QQC",'QA Log'!Z:Z,"Approved",'QA Log'!L:L,"*9. EPI and Pre-school Consultation*"), COUNTIFS('QA Log'!D:D,A3,'QA Log'!M:M,"QQC",'QA Log'!Z:Z,"Approved",'QA Log'!L:L,"*10. Antenatal Care (ANC)*"), COUNTIFS('QA Log'!D:D,A3,'QA Log'!M:M,"QQC",'QA Log'!Z:Z,"Approved",'QA Log'!L:L,"*2. Hygiene and Sterilization*"), COUNTIFS('QA Log'!D:D,A3,'QA Log'!M:M,"QQC",'QA Log'!Z:Z,"Approved",'QA Log'!L:L,"*4. Family Planning*") )) -> 0 | W3: =IF(A3<>"",COUNTIFS('QA Log'!D:D,A3,'QA Log'!M:M,"QQC",'QA Log'!L:L,"8. Maternity",'QA Log'!Z:Z,"Approved"),"") -> 0 | X3: =IF(A3<>"",COUNTIFS('QA Log'!D:D,A3,'QA Log'!M:M,"QQC",'QA Log'!L:L,"9. EPI and Pre-school Consultation",'QA Log'!Z:Z,"Approved"),"") -> 0 | Y3: =IF(A3<>"",COUNTIFS('QA Log'!D:D,A3,'QA Log'!M:M,"QQC",'QA Log'!L:L,"10. Antenatal Care (ANC)",'QA Log'!Z:Z,"Approved"),"") -> 0 | Z3: =IF(A3<>"",COUNTIFS('QA Log'!D:D,A3,'QA Log'!M:M,"QQC",'QA Log'!L:L,"2. Hygiene and Sterilization",'QA Log'!Z:Z,"Approved"),"") -> 0 | AA3: =IF(A3<>"",COUNTIFS('QA Log'!D:D,A3,'QA Log'!M:M,"QQC",'QA Log'!L:L,"4. Family Planning",'QA Log'!Z:Z,"Approved"),"") -> 0 | AB3: =IF(A3="","", SUM( COUNTIFS('QA Log'!D:D,A3,'QA Log'!M:M,"QQC",'QA Log'!Z:Z,"Rejected",'QA Log'!L:L,"*8. Maternity*"), COUNTIFS('QA Log'!D:D,A3,'QA Log'!M:M,"QQC",'QA Log'!Z:Z,"Rejected",'QA Log'!L:L,"*9. EPI and Pre-school Consultation*"), COUNTIFS('QA Log'!D:D,A3,'QA Log'!M:M,"QQC",'QA Log'!Z:Z,"Rejected",'QA Log'!L:L,"*10. Antenatal Care (ANC)*"), COUNTIFS('QA Log'!D:D,A3,'QA Log'!M:M,"QQC",'QA Log'!Z:Z,"Rejected",'QA Log'!L:L,"*2. Hygiene and Sterilization*"), COUNTIFS('QA Log'!D:D,A3,'QA Log'!M:M,"QQC",'QA Log'!Z:Z,"Rejected",'QA Log'!L:L,"*4. Family Planning*") )) -> 0 | AC3: =IF(A3<>"",T3-V3,"") -> #NAME? | AD3: =IF(A3="", "", IF(OR(D3="RH", D3="PH"), 4,IF(OR(D3="DH",D3="CHC",D3="BHC"),0, IF(D3="SHC", 2)) )) -> #NAME? | AE3: =IF(A3="","", SUM( COUNTIFS('QA Log'!D:D,A3,'QA Log'!M:M,"Data Verification",'QA Log'!L:L,"*Medicine (section 2)*"), COUNTIFS('QA Log'!D:D,A3,'QA Log'!M:M,"Data Verification",'QA Log'!L:L,"*Lab Testing Availability*"), COUNTIFS('QA Log'!D:D,A3,'QA Log'!M:M,"Data Verification",'QA Log'!L:L,"*Other than P4P (section 6)*"), COUNTIFS('QA Log'!D:D,A3,'QA Log'!M:M,"Data Verification",'QA Log'!L:L,"*Hospital Governance*") )) -> 2 | AF3: =IF(A3="","", SUM( COUNTIFS('QA Log'!D:D,A3,'QA Log'!M:M,"Data Verification",'QA Log'!Z:Z,"Approved",'QA Log'!L:L,"*Medicine (section 2)*"), COUNTIFS('QA Log'!D:D,A3,'QA Log'!M:M,"Data Verification",'QA Log'!Z:Z,"Approved",'QA Log'!L:L,"*Lab Testing Availability*"), COUNTIFS('QA Log'!D:D,A3,'QA Log'!M:M,"Data Verification",'QA Log'!Z:Z,"Approved",'QA Log'!L:L,"*Other than P4P (section 6)*"), COUNTIFS('QA Log'!D:D,A3,'QA Log'!M:M,"Data Verification",'QA Log'!Z:Z,"Approved",'QA Log'!L:L,"*Hospital Governance*") )) -> 2 | AG3: =IF(A3<>"",COUNTIFS('QA Log'!D:D,A3,'QA Log'!M:M,"Data Verification",'QA Log'!L:L,"Medicine (section 2)",'QA Log'!Z:Z,"Approved"),"") -> 1 | AH3: =IF(A3<>"",COUNTIFS('QA Log'!D:D,A3,'QA Log'!M:M,"Data Verification",'QA Log'!L:L,"Lab Testing Availability",'QA Log'!Z:Z,"Approved"),"") -> 0 | AI3: =IF(A3<>"",COUNTIFS('QA Log'!D:D,A3,'QA Log'!M:M,"Data Verification",'QA Log'!L:L,"Other than P4P (section 6)",'QA Log'!Z:Z,"Approved"),"") -> 1 | AJ3: =IF(A3<>"",COUNTIFS('QA Log'!D:D,A3,'QA Log'!M:M,"Data Verification",'QA Log'!L:L,"Hospital Governance",'QA Log'!Z:Z,"Approved"),"") -> 0 | AK3: =IF(A3="","", SUM( COUNTIFS('QA Log'!D:D,A3,'QA Log'!M:M,"Data Verification",'QA Log'!Z:Z,"Rejected",'QA Log'!L:L,"*Medicine (section 2)*"), COUNTIFS('QA Log'!D:D,A3,'QA Log'!M:M,"Data Verification",'QA Log'!Z:Z,"Rejected",'QA Log'!L:L,"*Lab Testing Availability*"), COUNTIFS('QA Log'!D:D,A3,'QA Log'!M:M,"Data Verification",'QA Log'!Z:Z,"Rejected",'QA Log'!L:L,"*Other than P4P (section 6)*"), COUNTIFS('QA Log'!D:D,A3,'QA Log'!M:M,"Data Verification",'QA Log'!Z:Z,"Rejected",'QA Log'!L:L,"*Hospital Governance*") )) -> 0 | AL3: =IF(A3<>"",AD3-AF3,"") -> #NAME? | AM3: =IF(A3="", "", IF(OR(D3="RH", D3="PH"), 3,IF(OR(D3="DH",D3="CHC",D3="BHC"),0, IF(D3="SHC", 3)) )) -> #NAME? | AN3: =IF(A3="","", SUM( COUNTIFS('QA Log'!D:D,A3,'QA Log'!M:M,"Data Verification",'QA Log'!L:L,"*Personnel (section 1)*"), COUNTIFS('QA Log'!D:D,A3,'QA Log'!M:M,"Data Verification",'QA Log'!L:L,"*Consumable (section 3)*"), COUNTIFS('QA Log'!D:D,A3,'QA Log'!M:M,"Data Verification",'QA Log'!L:L,"*Equipments (section 4)*") )) -> 3 | AO3: =IF(A3="","", SUM( COUNTIFS('QA Log'!D:D,A3,'QA Log'!M:M,"Data Verification",'QA Log'!Z:Z,"Approved",'QA Log'!L:L,"*Personnel (section 1)*"), COUNTIFS('QA Log'!D:D,A3,'QA Log'!M:M,"Data Verification",'QA Log'!Z:Z,"Approved",'QA Log'!L:L,"*Consumable (section 3)*"), COUNTIFS('QA Log'!D:D,A3,'QA Log'!M:M,"Data Verification",'QA Log'!Z:Z,"Approved",'QA Log'!L:L,"*Equipments (section 4)*") )) -> 3 | AP3: =IF(A3<>"",COUNTIFS('QA Log'!D:D,A3,'QA Log'!M:M,"Data Verification",'QA Log'!L:L,"Personnel (section 1)",'QA Log'!Z:Z,"Approved"),"") -> 1 | AQ3: =IF(A3<>"",COUNTIFS('QA Log'!D:D,A3,'QA Log'!M:M,"Data Verification",'QA Log'!L:L,"Consumable (section 3)",'QA Log'!Z:Z,"Approved"),"") -> 1 | AR3: =IF(A3<>"",COUNTIFS('QA Log'!D:D,A3,'QA Log'!M:M,"Data Verification",'QA Log'!L:L,"Equipments (section 4)",'QA Log'!Z:Z,"Approved"),"") -> 1 | AS3: =IF(A3="","", SUM( COUNTIFS('QA Log'!D:D,A3,'QA Log'!M:M,"Data Verification",'QA Log'!Z:Z,"Rejected",'QA Log'!L:L,"*Personnel (section 1)*"), COUNTIFS('QA Log'!D:D,A3,'QA Log'!M:M,"Data Verification",'QA Log'!Z:Z,"Rejected",'QA Log'!L:L,"*Consumable (section 3)*"), COUNTIFS('QA Log'!D:D,A3,'QA Log'!M:M,"Data Verification",'QA Log'!Z:Z,"Rejected",'QA Log'!L:L,"*Equipments (section 4)*") )) -> 0 | AT3: =IF(A3<>"",AM3-AO3,"") -> #NAME? | AU3: =IF(A3<>"",2,"") -> 2 | AV3: =IF(A3="","",SUM( COUNTIFS('QA Log'!D:D,A3,'QA Log'!M:M,"Vignette",'QA Log'!L:L,"*Vignette [1] Respiratory Infection: Pneumonia*"), COUNTIFS('QA Log'!D:D,A3,'QA Log'!M:M,"Vignette",'QA Log'!L:L,"*Vignette [2]: Diarrhea with Cat B dehydration*"), COUNTIFS('QA Log'!D:D,A3,'QA Log'!M:M,"Vignette",'QA Log'!L:L,"*Vignette [3] Growth Monitoring and Promotion*"), COUNTIFS('QA Log'!D:D,A3,'QA Log'!M:M,"Vignette",'QA Log'!L:L,"*Vignette [4]: The management of presumptive TB patient*") ) ) -> 3 | AW3: =IF(A3="","", SUM( COUNTIFS('QA Log'!D:D,A3,'QA Log'!M:M,"Vignette",'QA Log'!Z:Z,"Approved",'QA Log'!L:L,"*Vignette [1] Respiratory Infection: Pneumonia*"), COUNTIFS('QA Log'!D:D,A3,'QA Log'!M:M,"Vignette",'QA Log'!Z:Z,"Approved",'QA Log'!L:L,"*Vignette [2]: Diarrhea with Cat B dehydration*"), COUNTIFS('QA Log'!D:D,A3,'QA Log'!M:M,"Vignette",'QA Log'!Z:Z,"Approved",'QA Log'!L:L,"*Vignette [3] Growth Monitoring and Promotion*"), COUNTIFS('QA Log'!D:D,A3,'QA Log'!M:M,"Vignette",'QA Log'!Z:Z,"Approved",'QA Log'!L:L,"*Vignette [4]: The management of presumptive TB patient*") ) ) -> 3 | AX3: =IF(A3<>"",COUNTIFS('QA Log'!D:D,A3,'QA Log'!M:M,"Vignette",'QA Log'!L:L,"Vignette [1] Respiratory Infection: Pneumonia",'QA Log'!Z:Z,"Approved"),"") -> 1 | AY3: =IF(A3<>"",COUNTIFS('QA Log'!D:D,A3,'QA Log'!M:M,"Vignette",'QA Log'!L:L,"Vignette [2]: Diarrhea with Cat B dehydration",'QA Log'!Z:Z,"Approved"),"") -> 1 | AZ3: =IF(A3<>"",COUNTIFS('QA Log'!D:D,A3,'QA Log'!M:M,"Vignette",'QA Log'!L:L,"Vignette [3] Growth Monitoring and Promotion",'QA Log'!Z:Z,"Approved"),"") -> 1 | BA3: =IF(A3<>"",COUNTIFS('QA Log'!D:D,A3,'QA Log'!M:M,"Vignette",'QA Log'!L:L,"Vignette [4]: The management of presumptive TB patient",'QA Log'!Z:Z,"Approved"),"") -> 0 | BB3: =IF(A3="","", SUM( COUNTIFS('QA Log'!D:D,A3,'QA Log'!M:M,"Vignette",'QA Log'!Z:Z,"Rejected",'QA Log'!L:L,"*Vignette [1] Respiratory Infection: Pneumonia*"), COUNTIFS('QA Log'!D:D,A3,'QA Log'!M:M,"Vignette",'QA Log'!Z:Z,"Rejected",'QA Log'!L:L,"*Vignette [2]: Diarrhea with Cat B dehydration*"), COUNTIFS('QA Log'!D:D,A3,'QA Log'!M:M,"Vignette",'QA Log'!Z:Z,"Rejected",'QA Log'!L:L,"*Vignette [3] Growth Monitoring and Promotion*"), COUNTIFS('QA Log'!D:D,A3,'QA Log'!M:M,"Vignette",'QA Log'!Z:Z,"Rejected",'QA Log'!L:L,"*Vignette [4]: The management of presumptive TB patient*") ) ) -> 0 | BC3: =IF(A3<>"",AU3-AW3,"") -> -1 | BD3: =IF(J3<>"",2,"") -> 2 | BE3: =IF(A3="","",SUM( COUNTIFS('QA Log'!D:D,A3,'QA Log'!M:M,"Vignette",'QA Log'!L:L,"*Vignette [5] Labor*"), COUNTIFS('QA Log'!D:D,A3,'QA Log'!M:M,"Vignette",'QA Log'!L:L,"*Vignette [6] PNC pre Discharge*"), COUNTIFS('QA Log'!D:D,A3,'QA Log'!M:M,"Vignette",'QA Log'!L:L,"*Vignette [7] First ANC Visit*"), COUNTIFS('QA Log'!D:D,A3,'QA Log'!M:M,"Vignette",'QA Log'!L:L,"*Vignette [8] Birth Spacing/ Family Planning : FP Counselling*"), COUNTIFS('QA Log'!D:D,A3,'QA Log'!M:M,"Vignette",'QA Log'!L:L,"*Vignette [9] Birth Spacing: Change FP method to Injectable*"), COUNTIFS('QA Log'!D:D,A3,'QA Log'!M:M,"Vignette",'QA Log'!L:L,"*Vignette [10] Post Partum Haemorrhage - Atonic Uterus at Health Centre*"), ) ) -> 2 | BF3: =IF(A3="","", SUM( COUNTIFS('QA Log'!D:D,A3,'QA Log'!M:M,"Vignette",'QA Log'!Z:Z,"Approved",'QA Log'!L:L,"*Vignette [5] Labor*"), COUNTIFS('QA Log'!D:D,A3,'QA Log'!M:M,"Vignette",'QA Log'!Z:Z,"Approved",'QA Log'!L:L,"*Vignette [6] PNC pre Discharge*"), COUNTIFS('QA Log'!D:D,A3,'QA Log'!M:M,"Vignette",'QA Log'!Z:Z,"Approved",'QA Log'!L:L,"*Vignette [7] First ANC Visit*"), COUNTIFS('QA Log'!D:D,A3,'QA Log'!M:M,"Vignette",'QA Log'!Z:Z,"Approved",'QA Log'!L:L,"*Vignette [8] Birth Spacing/ Family Planning : FP Counselling*"), COUNTIFS('QA Log'!D:D,A3,'QA Log'!M:M,"Vignette",'QA Log'!Z:Z,"Approved",'QA Log'!L:L,"*Vignette [9] Birth Spacing: Change FP method to Injectable*"), COUNTIFS('QA Log'!D:D,A3,'QA Log'!M:M,"Vignette",'QA Log'!Z:Z,"Approved",'QA Log'!L:L,"*Vignette [10] Post Partum Haemorrhage - Atonic Uterus at Health Centre*") ) ) -> 2 | BG3: =IF(A3<>"",COUNTIFS('QA Log'!D:D,A3,'QA Log'!M:M,"Vignette",'QA Log'!L:L,"Vignette [5] Labor",'QA Log'!Z:Z,"Approved"),"") -> 1 | BH3: =IF(A3<>"",COUNTIFS('QA Log'!D:D,A3,'QA Log'!M:M,"Vignette",'QA Log'!L:L,"Vignette [6] PNC pre Discharge",'QA Log'!Z:Z,"Approved"),"") -> 1 | BI3: =IF(A3<>"",COUNTIFS('QA Log'!D:D,A3,'QA Log'!M:M,"Vignette",'QA Log'!L:L,"Vignette [7] First ANC Visit",'QA Log'!Z:Z,"Approved"),"") -> 0 | BJ3: =IF(A3<>"",COUNTIFS('QA Log'!D:D,A3,'QA Log'!M:M,"Vignette",'QA Log'!L:L,"Vignette [8] Birth Spacing/ Family Planning : FP Counselling",'QA Log'!Z:Z,"Approved"),"") -> 0 | BK3: =IF(A3<>"",COUNTIFS('QA Log'!D:D,A3,'QA Log'!M:M,"Vignette",'QA Log'!L:L,"Vignette [9] Birth Spacing: Change FP method to Injectable",'QA Log'!Z:Z,"Approved"),"") -> 0 | BL3: =IF(A3<>"",COUNTIFS('QA Log'!D:D,A3,'QA Log'!M:M,"Vignette",'QA Log'!L:L,"Vignette [10] Post Partum Haemorrhage - Atonic Uterus at Health Centre",'QA Log'!Z:Z,"Approved"),"") -> 0 | BM3: =IF(A3="","",SUM( COUNTIFS('QA Log'!D:D,A3,'QA Log'!M:M,"Vignette",'QA Log'!Z:Z,"Rejected",'QA Log'!L:L,"*Vignette [5] Labor*"), COUNTIFS('QA Log'!D:D,A3,'QA Log'!M:M,"Vignette",'QA Log'!Z:Z,"Rejected",'QA Log'!L:L,"*Vignette [6] PNC pre Discharge*"), COUNTIFS('QA Log'!D:D,A3,'QA Log'!M:M,"Vignette",'QA Log'!Z:Z,"Rejected",'QA Log'!L:L,"*Vignette [7] First ANC Visit*"), COUNTIFS('QA Log'!D:D,A3,'QA Log'!M:M,"Vignette",'QA Log'!Z:Z,"Rejected",'QA Log'!L:L,"*Vignette [8] Birth Spacing/ Family Planning : FP Counselling*"), COUNTIFS('QA Log'!D:D,A3,'QA Log'!M:M,"Vignette",'QA Log'!Z:Z,"Rejected",'QA Log'!L:L,"*Vignette [9] Birth Spacing: Change FP method to Injectable*"), COUNTIFS('QA Log'!D:D,A3,'QA Log'!M:M,"Vignette",'QA Log'!Z:Z,"Rejected",'QA Log'!L:L,"*Vignette [10] Post Partum Haemorrhage - Atonic Uterus at Health Centre*") ) ) -> 0 | BN3: =IF(A3<>"",BD3-BF3,"") -> 0 | BO3: =IF(A3<>"",2,"") -> 2 | BP3: =IF(A3="","",SUM( COUNTIFS('QA Log'!D:D,A3,'QA Log'!M:M,"Vignette",'QA Log'!L:L,"*Exit Interview 1*"), COUNTIFS('QA Log'!D:D,A3,'QA Log'!M:M,"Vignette",'QA Log'!L:L,"*Exit Interview 2*"), ) ) -> 2 | BQ3: =IF( A3="","", SUM( COUNTIFS('QA Log'!D:D,A3,'QA Log'!M:M,"Vignette",'QA Log'!Z:Z,"Approved",'QA Log'!L:L,"*Exit Interview 1*"), COUNTIFS('QA Log'!D:D,A3,'QA Log'!M:M,"Vignette",'QA Log'!Z:Z,"Approved",'QA Log'!L:L,"*Exit Interview 2*") ) ) -> 2 | BR3: =IF(A3<>"",COUNTIFS('QA Log'!D:D,A3,'QA Log'!M:M,"Vignette",'QA Log'!L:L,"Exit Interview 1",'QA Log'!Z:Z,"Approved"),"") -> 1 | BS3: =IF(A3<>"",COUNTIFS('QA Log'!D:D,A3,'QA Log'!M:M,"Vignette",'QA Log'!L:L,"Exit Interview 2",'QA Log'!Z:Z,"Approved"),"") -> 1 | BT3: =IF( A3="","", SUM( COUNTIFS('QA Log'!D:D,A3,'QA Log'!M:M,"Vignette",'QA Log'!Z:Z,"Rejected",'QA Log'!L:L,"*Exit Interview 1*"), COUNTIFS('QA Log'!D:D,A3,'QA Log'!M:M,"Vignette",'QA Log'!Z:Z,"Rejected",'QA Log'!L:L,"*Exit Interview 2*") ) ) -> 0 | BU3: =IF(A3<>"",BO3-BQ3,"") -> 0 | BV3: =IF(A3<>"",SUM(BO3,BD3,AU3,AM3,AD3,T3,I3),"") -> #NAME? | BW3: =IF(A3<>"",SUM(BP3,BE3,AV3,AN3,AE3,U3,J3),"") -> 12 | BX3: =IF(A3<>"",SUM(BQ3,BF3,AW3,AO3,AF3,V3,K3),"") -> 12 | BY3: =IF(A3<>"",SUM(BT3,BM3,BB3,AS3,AK3,AB3,R3),"") -> 0 | BZ3: =IF(A3<>"",BV3-BX3,"") -> #NAME? | CA3: =IF( A3="","", IF( OR(D3="RH",D3="PH",D3="SHC"), "Not Applicable", IF(AND(I3<=J3,T3<=U3),"Fully Received","Not Received") ) ) -> #NAME? | CB3: =IF(A3<>"", IF(OR(D3="DH",D3="CHC",D3="BHC"),"Not Applicable",IF(AND(AD3<=AE3,AM3<=AN3),"Fully Received","Not Received")),"") -> #NAME? | CC3: =IF(A3<>"",IF(AND(AU3<=AV3,BD3<=BE3,BO3<=BP3),"Fully Received","Not Received"),"") -> Fully Received | CD3: =IF( A3="","", IF( OR(D3="RH",D3="PH",D3="SHC"), "Not Applicable", IF(AND(I3<=K3,T3<=V3),"Fully Received","Not Received") ) ) -> #NAME? | CE3: =IF(A3<>"",IF(OR(D3="DH",D3="CHC",D3="BHC"),"Not Applicable",IF(AND(AD3<=AF3,AM3<=AO3),"Fully Received","Not Received")),"") -> #NAME? | CF3: =IF(A3<>"",IF(AND(AU3<=AW3,BD3<=BF3,BO3<=BQ3),"Fully Received","Not Received"),"") -> Fully Received | CG3: =IF(A3<>"",IF(AND(CD3="Fully Received", CE3="Fully Received", CF3="Fully Received"),"Completed Based on Data",IF(AND(CD3="Not Received", CE3="Not Received", CF3="Not Received"),"Not Completed Based on Data","Partially Completed")),"") -> #NAME?
A4: =IFERROR(__xludf.DUMMYFUNCTION("""COMPUTED_VALUE"""),"HER-PKA-HF1630-Q2-2025-1189-01") -> HER-PKA-HF1630-Q2-2025-1189-01 | B4: {=_xludf.XLOOKUP(A4,'QA Log'!D:D,'QA Log'!E:E,"")} -> #NAME? | C4: {=_xludf.XLOOKUP(A4,'QA Log'!D:D,'QA Log'!F:F,"")} -> #NAME? | D4: {=_xludf.XLOOKUP(A4,'QA Log'!D:D,'QA Log'!H:H,"")} -> #NAME? | E4: {=_xludf.XLOOKUP(A4,'QA Log'!D:D,'QA Log'!G:G,"")} -> #NAME? | F4: Completed | G4: 45959 | H4: Novumber 1,2025 | I4: =IF(A4="", "", IF(OR(D4="RH", D4="PH", D4="SHC"), 0, IF(D4="BHC", 5, 6))) -> #NAME? | J4: =IF(A4="","",SUM( COUNTIFS('QA Log'!D:D,A4,'QA Log'!M:M,"QQC",'QA Log'!L:L,"*1. General Management*"), COUNTIFS('QA Log'!D:D,A4,'QA Log'!M:M,"QQC",'QA Log'!L:L,"*3. Curative Consultation (OPD)*"), COUNTIFS('QA Log'!D:D,A4,'QA Log'!M:M,"QQC",'QA Log'!L:L,"*5. Laboratory*"), COUNTIFS('QA Log'!D:D,A4,'QA Log'!M:M,"QQC",'QA Log'!L:L,"*6. Essential Medicine Management*"), COUNTIFS('QA Log'!D:D,A4,'QA Log'!M:M,"QQC",'QA Log'!L:L,"*7. Tracer Medicine*"), COUNTIFS('QA Log'!D:D,A4,'QA Log'!M:M,"QQC",'QA Log'!L:L,"*11. Additional Questions*"))) -> 6 | K4: =IF(A4="","",SUM( COUNTIFS('QA Log'!D:D,A4,'QA Log'!M:M,"QQC",'QA Log'!Z:Z,"Approved",'QA Log'!L:L,"*1. General Management*"), COUNTIFS('QA Log'!D:D,A4,'QA Log'!M:M,"QQC",'QA Log'!Z:Z,"Approved",'QA Log'!L:L,"*3. Curative Consultation (OPD)*"), COUNTIFS('QA Log'!D:D,A4,'QA Log'!M:M,"QQC",'QA Log'!Z:Z,"Approved",'QA Log'!L:L,"*5. Laboratory*"), COUNTIFS('QA Log'!D:D,A4,'QA Log'!M:M,"QQC",'QA Log'!Z:Z,"Approved",'QA Log'!L:L,"*6. Essential Medicine Management*"), COUNTIFS('QA Log'!D:D,A4,'QA Log'!M:M,"QQC",'QA Log'!Z:Z,"Approved",'QA Log'!L:L,"*7. Tracer Medicine*"), COUNTIFS('QA Log'!D:D,A4,'QA Log'!M:M,"QQC",'QA Log'!Z:Z,"Approved",'QA Log'!L:L,"*11. Additional Questions*"))) -> 4 | L4: =IF(A4<>"",COUNTIFS('QA Log'!D:D,A4,'QA Log'!M:M,"QQC",'QA Log'!L:L,"1. General Management",'QA Log'!Z:Z,"Approved"),"") -> 1 | M4: =IF(A4<>"",COUNTIFS('QA Log'!D:D,A4,'QA Log'!M:M,"QQC",'QA Log'!L:L,"3. Curative Consultation (OPD)",'QA Log'!Z:Z,"Approved"),"") -> 1 | N4: =IF(A4<>"",COUNTIFS('QA Log'!D:D,A4,'QA Log'!M:M,"QQC",'QA Log'!L:L,"5. Laboratory",'QA Log'!Z:Z,"Approved"),"") -> 1 | O4: =IF(A4<>"",COUNTIFS('QA Log'!D:D,A4,'QA Log'!M:M,"QQC",'QA Log'!L:L,"6. Essential Medicine Management",'QA Log'!Z:Z,"Approved"),"") -> 0 | P4: =IF(A4<>"",COUNTIFS('QA Log'!D:D,A4,'QA Log'!M:M,"QQC",'QA Log'!L:L,"7. Tracer Medicine",'QA Log'!Z:Z,"Approved"),"") -> 0 | Q4: =IF(A4<>"",COUNTIFS('QA Log'!D:D,A4,'QA Log'!M:M,"QQC",'QA Log'!L:L,"11. Additional Questions",'QA Log'!Z:Z,"Approved"),"") -> 1 | R4: =IF(A4="","",SUM( COUNTIFS('QA Log'!D:D,A4,'QA Log'!M:M,"QQC",'QA Log'!Z:Z,"Rejected",'QA Log'!L:L,"*8. Maternity*"), COUNTIFS('QA Log'!D:D,A4,'QA Log'!M:M,"QQC",'QA Log'!Z:Z,"Rejected",'QA Log'!L:L,"*EPI*"), COUNTIFS('QA Log'!D:D,A4,'QA Log'!M:M,"QQC",'QA Log'!Z:Z,"Rejected",'QA Log'!L:L,"*10. Antenatal Care (ANC)*"), COUNTIFS('QA Log'!D:D,A4,'QA Log'!M:M,"QQC",'QA Log'!Z:Z,"Rejected",'QA Log'!L:L,"*2. Hygiene and Sterilization*"), COUNTIFS('QA Log'!D:D,A4,'QA Log'!M:M,"QQC",'QA Log'!Z:Z,"Rejected",'QA Log'!L:L,"*Family Planning*"))) -> 0 | S4: =IF(A4<>"",I4-K4,"") -> #NAME? | T4: =IF(A4="", "", IF(OR(D4="RH", D4="PH", D4="SHC"), 0, IF(D4="BHC", 5, 5))) -> #NAME? | U4: =IF(A4="","", SUM( COUNTIFS('QA Log'!D:D,A4,'QA Log'!M:M,"QQC",'QA Log'!L:L,"*8. Maternity*"), COUNTIFS('QA Log'!D:D,A4,'QA Log'!M:M,"QQC",'QA Log'!L:L,"*9. EPI and Pre-school Consultation*"), COUNTIFS('QA Log'!D:D,A4,'QA Log'!M:M,"QQC",'QA Log'!L:L,"*10. Antenatal Care (ANC)*"), COUNTIFS('QA Log'!D:D,A4,'QA Log'!M:M,"QQC",'QA Log'!L:L,"*2. Hygiene and Sterilization*"), COUNTIFS('QA Log'!D:D,A4,'QA Log'!M:M,"QQC",'QA Log'!L:L,"*4. Family Planning*") )) -> 4 | V4: =IF(A4="","", SUM( COUNTIFS('QA Log'!D:D,A4,'QA Log'!M:M,"QQC",'QA Log'!Z:Z,"Approved",'QA Log'!L:L,"*8. Maternity*"), COUNTIFS('QA Log'!D:D,A4,'QA Log'!M:M,"QQC",'QA Log'!Z:Z,"Approved",'QA Log'!L:L,"*9. EPI and Pre-school Consultation*"), COUNTIFS('QA Log'!D:D,A4,'QA Log'!M:M,"QQC",'QA Log'!Z:Z,"Approved",'QA Log'!L:L,"*10. Antenatal Care (ANC)*"), COUNTIFS('QA Log'!D:D,A4,'QA Log'!M:M,"QQC",'QA Log'!Z:Z,"Approved",'QA Log'!L:L,"*2. Hygiene and Sterilization*"), COUNTIFS('QA Log'!D:D,A4,'QA Log'!M:M,"QQC",'QA Log'!Z:Z,"Approved",'QA Log'!L:L,"*4. Family Planning*") )) -> 4 | W4: =IF(A4<>"",COUNTIFS('QA Log'!D:D,A4,'QA Log'!M:M,"QQC",'QA Log'!L:L,"8. Maternity",'QA Log'!Z:Z,"Approved"),"") -> 2 | X4: =IF(A4<>"",COUNTIFS('QA Log'!D:D,A4,'QA Log'!M:M,"QQC",'QA Log'!L:L,"9. EPI and Pre-school Consultation",'QA Log'!Z:Z,"Approved"),"") -> 0 | Y4: =IF(A4<>"",COUNTIFS('QA Log'!D:D,A4,'QA Log'!M:M,"QQC",'QA Log'!L:L,"10. Antenatal Care (ANC)",'QA Log'!Z:Z,"Approved"),"") -> 1 | Z4: =IF(A4<>"",COUNTIFS('QA Log'!D:D,A4,'QA Log'!M:M,"QQC",'QA Log'!L:L,"2. Hygiene and Sterilization",'QA Log'!Z:Z,"Approved"),"") -> 1 | AA4: =IF(A4<>"",COUNTIFS('QA Log'!D:D,A4,'QA Log'!M:M,"QQC",'QA Log'!L:L,"4. Family Planning",'QA Log'!Z:Z,"Approved"),"") -> 0 | AB4: =IF(A4="","", SUM( COUNTIFS('QA Log'!D:D,A4,'QA Log'!M:M,"QQC",'QA Log'!Z:Z,"Rejected",'QA Log'!L:L,"*8. Maternity*"), COUNTIFS('QA Log'!D:D,A4,'QA Log'!M:M,"QQC",'QA Log'!Z:Z,"Rejected",'QA Log'!L:L,"*9. EPI and Pre-school Consultation*"), COUNTIFS('QA Log'!D:D,A4,'QA Log'!M:M,"QQC",'QA Log'!Z:Z,"Rejected",'QA Log'!L:L,"*10. Antenatal Care (ANC)*"), COUNTIFS('QA Log'!D:D,A4,'QA Log'!M:M,"QQC",'QA Log'!Z:Z,"Rejected",'QA Log'!L:L,"*2. Hygiene and Sterilization*"), COUNTIFS('QA Log'!D:D,A4,'QA Log'!M:M,"QQC",'QA Log'!Z:Z,"Rejected",'QA Log'!L:L,"*4. Family Planning*") )) -> 0 | AC4: =IF(A4<>"",T4-V4,"") -> #NAME? | AD4: =IF(A4="", "", IF(OR(D4="RH", D4="PH"), 4,IF(OR(D4="DH",D4="CHC",D4="BHC"),0, IF(D4="SHC", 2)) )) -> #NAME? | AE4: =IF(A4="","", SUM( COUNTIFS('QA Log'!D:D,A4,'QA Log'!M:M,"Data Verification",'QA Log'!L:L,"*Medicine (section 2)*"), COUNTIFS('QA Log'!D:D,A4,'QA Log'!M:M,"Data Verification",'QA Log'!L:L,"*Lab Testing Availability*"), COUNTIFS('QA Log'!D:D,A4,'QA Log'!M:M,"Data Verification",'QA Log'!L:L,"*Other than P4P (section 6)*"), COUNTIFS('QA Log'!D:D,A4,'QA Log'!M:M,"Data Verification",'QA Log'!L:L,"*Hospital Governance*") )) -> 0 | AF4: =IF(A4="","", SUM( COUNTIFS('QA Log'!D:D,A4,'QA Log'!M:M,"Data Verification",'QA Log'!Z:Z,"Approved",'QA Log'!L:L,"*Medicine (section 2)*"), COUNTIFS('QA Log'!D:D,A4,'QA Log'!M:M,"Data Verification",'QA Log'!Z:Z,"Approved",'QA Log'!L:L,"*Lab Testing Availability*"), COUNTIFS('QA Log'!D:D,A4,'QA Log'!M:M,"Data Verification",'QA Log'!Z:Z,"Approved",'QA Log'!L:L,"*Other than P4P (section 6)*"), COUNTIFS('QA Log'!D:D,A4,'QA Log'!M:M,"Data Verification",'QA Log'!Z:Z,"Approved",'QA Log'!L:L,"*Hospital Governance*") )) -> 0 | AG4: =IF(A4<>"",COUNTIFS('QA Log'!D:D,A4,'QA Log'!M:M,"Data Verification",'QA Log'!L:L,"Medicine (section 2)",'QA Log'!Z:Z,"Approved"),"") -> 0 | AH4: =IF(A4<>"",COUNTIFS('QA Log'!D:D,A4,'QA Log'!M:M,"Data Verification",'QA Log'!L:L,"Lab Testing Availability",'QA Log'!Z:Z,"Approved"),"") -> 0 | AI4: =IF(A4<>"",COUNTIFS('QA Log'!D:D,A4,'QA Log'!M:M,"Data Verification",'QA Log'!L:L,"Other than P4P (section 6)",'QA Log'!Z:Z,"Approved"),"") -> 0 | AJ4: =IF(A4<>"",COUNTIFS('QA Log'!D:D,A4,'QA Log'!M:M,"Data Verification",'QA Log'!L:L,"Hospital Governance",'QA Log'!Z:Z,"Approved"),"") -> 0 | AK4: =IF(A4="","", SUM( COUNTIFS('QA Log'!D:D,A4,'QA Log'!M:M,"Data Verification",'QA Log'!Z:Z,"Rejected",'QA Log'!L:L,"*Medicine (section 2)*"), COUNTIFS('QA Log'!D:D,A4,'QA Log'!M:M,"Data Verification",'QA Log'!Z:Z,"Rejected",'QA Log'!L:L,"*Lab Testing Availability*"), COUNTIFS('QA Log'!D:D,A4,'QA Log'!M:M,"Data Verification",'QA Log'!Z:Z,"Rejected",'QA Log'!L:L,"*Other than P4P (section 6)*"), COUNTIFS('QA Log'!D:D,A4,'QA Log'!M:M,"Data Verification",'QA Log'!Z:Z,"Rejected",'QA Log'!L:L,"*Hospital Governance*") )) -> 0 | AL4: =IF(A4<>"",AD4-AF4,"") -> #NAME? | AM4: =IF(A4="", "", IF(OR(D4="RH", D4="PH"), 3,IF(OR(D4="DH",D4="CHC",D4="BHC"),0, IF(D4="SHC", 3)) )) -> #NAME? | AN4: =IF(A4="","", SUM( COUNTIFS('QA Log'!D:D,A4,'QA Log'!M:M,"Data Verification",'QA Log'!L:L,"*Personnel (section 1)*"), COUNTIFS('QA Log'!D:D,A4,'QA Log'!M:M,"Data Verification",'QA Log'!L:L,"*Consumable (section 3)*"), COUNTIFS('QA Log'!D:D,A4,'QA Log'!M:M,"Data Verification",'QA Log'!L:L,"*Equipments (section 4)*") )) -> 0 | AO4: =IF(A4="","", SUM( COUNTIFS('QA Log'!D:D,A4,'QA Log'!M:M,"Data Verification",'QA Log'!Z:Z,"Approved",'QA Log'!L:L,"*Personnel (section 1)*"), COUNTIFS('QA Log'!D:D,A4,'QA Log'!M:M,"Data Verification",'QA Log'!Z:Z,"Approved",'QA Log'!L:L,"*Consumable (section 3)*"), COUNTIFS('QA Log'!D:D,A4,'QA Log'!M:M,"Data Verification",'QA Log'!Z:Z,"Approved",'QA Log'!L:L,"*Equipments (section 4)*") )) -> 0 | AP4: =IF(A4<>"",COUNTIFS('QA Log'!D:D,A4,'QA Log'!M:M,"Data Verification",'QA Log'!L:L,"Personnel (section 1)",'QA Log'!Z:Z,"Approved"),"") -> 0 | AQ4: =IF(A4<>"",COUNTIFS('QA Log'!D:D,A4,'QA Log'!M:M,"Data Verification",'QA Log'!L:L,"Consumable (section 3)",'QA Log'!Z:Z,"Approved"),"") -> 0 | AR4: =IF(A4<>"",COUNTIFS('QA Log'!D:D,A4,'QA Log'!M:M,"Data Verification",'QA Log'!L:L,"Equipments (section 4)",'QA Log'!Z:Z,"Approved"),"") -> 0 | AS4: =IF(A4="","", SUM( COUNTIFS('QA Log'!D:D,A4,'QA Log'!M:M,"Data Verification",'QA Log'!Z:Z,"Rejected",'QA Log'!L:L,"*Personnel (section 1)*"), COUNTIFS('QA Log'!D:D,A4,'QA Log'!M:M,"Data Verification",'QA Log'!Z:Z,"Rejected",'QA Log'!L:L,"*Consumable (section 3)*"), COUNTIFS('QA Log'!D:D,A4,'QA Log'!M:M,"Data Verification",'QA Log'!Z:Z,"Rejected",'QA Log'!L:L,"*Equipments (section 4)*") )) -> 0 | AT4: =IF(A4<>"",AM4-AO4,"") -> #NAME? | AU4: =IF(A4<>"",2,"") -> 2 | AV4: =IF(A4="","",SUM( COUNTIFS('QA Log'!D:D,A4,'QA Log'!M:M,"Vignette",'QA Log'!L:L,"*Vignette [1] Respiratory Infection: Pneumonia*"), COUNTIFS('QA Log'!D:D,A4,'QA Log'!M:M,"Vignette",'QA Log'!L:L,"*Vignette [2]: Diarrhea with Cat B dehydration*"), COUNTIFS('QA Log'!D:D,A4,'QA Log'!M:M,"Vignette",'QA Log'!L:L,"*Vignette [3] Growth Monitoring and Promotion*"), COUNTIFS('QA Log'!D:D,A4,'QA Log'!M:M,"Vignette",'QA Log'!L:L,"*Vignette [4]: The management of presumptive TB patient*") ) ) -> 4 | AW4: =IF( A4="","", SUM( COUNTIFS('QA Log'!D:D,A4,'QA Log'!M:M,"Vignette",'QA Log'!Z:Z,"Approved",'QA Log'!L:L,"*Vignette [1] Respiratory Infection: Pneumonia*"), COUNTIFS('QA Log'!D:D,A4,'QA Log'!M:M,"Vignette",'QA Log'!Z:Z,"Approved",'QA Log'!L:L,"*Vignette [2]: Diarrhea with Cat B dehydration*"), COUNTIFS('QA Log'!D:D,A4,'QA Log'!M:M,"Vignette",'QA Log'!Z:Z,"Approved",'QA Log'!L:L,"*Vignette [3] Growth Monitoring and Promotion*"), COUNTIFS('QA Log'!D:D,A4,'QA Log'!M:M,"Vignette",'QA Log'!Z:Z,"Approved",'QA Log'!L:L,"*Vignette [4]: The management of presumptive TB patient*") ) ) -> 0 | AX4: =IF(A4<>"",COUNTIFS('QA Log'!D:D,A4,'QA Log'!M:M,"Vignette",'QA Log'!L:L,"Vignette [1] Respiratory Infection: Pneumonia",'QA Log'!Z:Z,"Approved"),"") -> 0 | AY4: =IF(A4<>"",COUNTIFS('QA Log'!D:D,A4,'QA Log'!M:M,"Vignette",'QA Log'!L:L,"Vignette [2]: Diarrhea with Cat B dehydration",'QA Log'!Z:Z,"Approved"),"") -> 0 | AZ4: =IF(A4<>"",COUNTIFS('QA Log'!D:D,A4,'QA Log'!M:M,"Vignette",'QA Log'!L:L,"Vignette [3] Growth Monitoring and Promotion",'QA Log'!Z:Z,"Approved"),"") -> 0 | BA4: =IF(A4<>"",COUNTIFS('QA Log'!D:D,A4,'QA Log'!M:M,"Vignette",'QA Log'!L:L,"Vignette [4]: The management of presumptive TB patient",'QA Log'!Z:Z,"Approved"),"") -> 0 | BB4: =IF(A4="","", SUM( COUNTIFS('QA Log'!D:D,A4,'QA Log'!M:M,"Vignette",'QA Log'!Z:Z,"Rejected",'QA Log'!L:L,"*Vignette [1] Respiratory Infection: Pneumonia*"), COUNTIFS('QA Log'!D:D,A4,'QA Log'!M:M,"Vignette",'QA Log'!Z:Z,"Rejected",'QA Log'!L:L,"*Vignette [2]: Diarrhea with Cat B dehydration*"), COUNTIFS('QA Log'!D:D,A4,'QA Log'!M:M,"Vignette",'QA Log'!Z:Z,"Rejected",'QA Log'!L:L,"*Vignette [3] Growth Monitoring and Promotion*"), COUNTIFS('QA Log'!D:D,A4,'QA Log'!M:M,"Vignette",'QA Log'!Z:Z,"Rejected",'QA Log'!L:L,"*Vignette [4]: The management of presumptive TB patient*") ) ) -> 0 | BC4: =IF(A4<>"",AU4-AW4,"") -> 2 | BD4: =IF(J4<>"",2,"") -> 2 | BE4: =IF(A4="","",SUM( COUNTIFS('QA Log'!D:D,A4,'QA Log'!M:M,"Vignette",'QA Log'!L:L,"*Vignette [5] Labor*"), COUNTIFS('QA Log'!D:D,A4,'QA Log'!M:M,"Vignette",'QA Log'!L:L,"*Vignette [6] PNC pre Discharge*"), COUNTIFS('QA Log'!D:D,A4,'QA Log'!M:M,"Vignette",'QA Log'!L:L,"*Vignette [7] First ANC Visit*"), COUNTIFS('QA Log'!D:D,A4,'QA Log'!M:M,"Vignette",'QA Log'!L:L,"*Vignette [8] Birth Spacing/ Family Planning : FP Counselling*"), COUNTIFS('QA Log'!D:D,A4,'QA Log'!M:M,"Vignette",'QA Log'!L:L,"*Vignette [9] Birth Spacing: Change FP method to Injectable*"), COUNTIFS('QA Log'!D:D,A4,'QA Log'!M:M,"Vignette",'QA Log'!L:L,"*Vignette [10] Post Partum Haemorrhage - Atonic Uterus at Health Centre*"), ) ) -> 7 | BF4: =IF(A4="","", SUM( COUNTIFS('QA Log'!D:D,A4,'QA Log'!M:M,"Vignette",'QA Log'!Z:Z,"Approved",'QA Log'!L:L,"*Vignette [5] Labor*"), COUNTIFS('QA Log'!D:D,A4,'QA Log'!M:M,"Vignette",'QA Log'!Z:Z,"Approved",'QA Log'!L:L,"*Vignette [6] PNC pre Discharge*"), COUNTIFS('QA Log'!D:D,A4,'QA Log'!M:M,"Vignette",'QA Log'!Z:Z,"Approved",'QA Log'!L:L,"*Vignette [7] First ANC Visit*"), COUNTIFS('QA Log'!D:D,A4,'QA Log'!M:M,"Vignette",'QA Log'!Z:Z,"Approved",'QA Log'!L:L,"*Vignette [8] Birth Spacing/ Family Planning : FP Counselling*"), COUNTIFS('QA Log'!D:D,A4,'QA Log'!M:M,"Vignette",'QA Log'!Z:Z,"Approved",'QA Log'!L:L,"*Vignette [9] Birth Spacing: Change FP method to Injectable*"), COUNTIFS('QA Log'!D:D,A4,'QA Log'!M:M,"Vignette",'QA Log'!Z:Z,"Approved",'QA Log'!L:L,"*Vignette [10] Post Partum Haemorrhage - Atonic Uterus at Health Centre*") ) ) -> 0 | BG4: =IF(A4<>"",COUNTIFS('QA Log'!D:D,A4,'QA Log'!M:M,"Vignette",'QA Log'!L:L,"Vignette [5] Labor",'QA Log'!Z:Z,"Approved"),"") -> 0 | BH4: =IF(A4<>"",COUNTIFS('QA Log'!D:D,A4,'QA Log'!M:M,"Vignette",'QA Log'!L:L,"Vignette [6] PNC pre Discharge",'QA Log'!Z:Z,"Approved"),"") -> 0 | BI4: =IF(A4<>"",COUNTIFS('QA Log'!D:D,A4,'QA Log'!M:M,"Vignette",'QA Log'!L:L,"Vignette [7] First ANC Visit",'QA Log'!Z:Z,"Approved"),"") -> 0 | BJ4: =IF(A4<>"",COUNTIFS('QA Log'!D:D,A4,'QA Log'!M:M,"Vignette",'QA Log'!L:L,"Vignette [8] Birth Spacing/ Family Planning : FP Counselling",'QA Log'!Z:Z,"Approved"),"") -> 0 | BK4: =IF(A4<>"",COUNTIFS('QA Log'!D:D,A4,'QA Log'!M:M,"Vignette",'QA Log'!L:L,"Vignette [9] Birth Spacing: Change FP method to Injectable",'QA Log'!Z:Z,"Approved"),"") -> 0 | BL4: =IF(A4<>"",COUNTIFS('QA Log'!D:D,A4,'QA Log'!M:M,"Vignette",'QA Log'!L:L,"Vignette [10] Post Partum Haemorrhage - Atonic Uterus at Health Centre",'QA Log'!Z:Z,"Approved"),"") -> 0 | BM4: =IF(A4="","",SUM( COUNTIFS('QA Log'!D:D,A4,'QA Log'!M:M,"Vignette",'QA Log'!Z:Z,"Rejected",'QA Log'!L:L,"*Vignette [5] Labor*"), COUNTIFS('QA Log'!D:D,A4,'QA Log'!M:M,"Vignette",'QA Log'!Z:Z,"Rejected",'QA Log'!L:L,"*Vignette [6] PNC pre Discharge*"), COUNTIFS('QA Log'!D:D,A4,'QA Log'!M:M,"Vignette",'QA Log'!Z:Z,"Rejected",'QA Log'!L:L,"*Vignette [7] First ANC Visit*"), COUNTIFS('QA Log'!D:D,A4,'QA Log'!M:M,"Vignette",'QA Log'!Z:Z,"Rejected",'QA Log'!L:L,"*Vignette [8] Birth Spacing/ Family Planning : FP Counselling*"), COUNTIFS('QA Log'!D:D,A4,'QA Log'!M:M,"Vignette",'QA Log'!Z:Z,"Rejected",'QA Log'!L:L,"*Vignette [9] Birth Spacing: Change FP method to Injectable*"), COUNTIFS('QA Log'!D:D,A4,'QA Log'!M:M,"Vignette",'QA Log'!Z:Z,"Rejected",'QA Log'!L:L,"*Vignette [10] Post Partum Haemorrhage - Atonic Uterus at Health Centre*") ) ) -> 0 | BN4: =IF(A4<>"",BD4-BF4,"") -> 2 | BO4: =IF(A4<>"",2,"") -> 2 | BP4: =IF(A4="","",SUM( COUNTIFS('QA Log'!D:D,A4,'QA Log'!M:M,"Vignette",'QA Log'!L:L,"*Exit Interview 1*"), COUNTIFS('QA Log'!D:D,A4,'QA Log'!M:M,"Vignette",'QA Log'!L:L,"*Exit Interview 2*"), ) ) -> 2 | BQ4: =IF( A4="","", SUM( COUNTIFS('QA Log'!D:D,A4,'QA Log'!M:M,"Vignette",'QA Log'!Z:Z,"Approved",'QA Log'!L:L,"*Exit Interview 1*"), COUNTIFS('QA Log'!D:D,A4,'QA Log'!M:M,"Vignette",'QA Log'!Z:Z,"Approved",'QA Log'!L:L,"*Exit Interview 2*") ) ) -> 0 | BR4: =IF(A4<>"",COUNTIFS('QA Log'!D:D,A4,'QA Log'!M:M,"Vignette",'QA Log'!L:L,"Exit Interview 1",'QA Log'!Z:Z,"Approved"),"") -> 0 | BS4: =IF(A4<>"",COUNTIFS('QA Log'!D:D,A4,'QA Log'!M:M,"Vignette",'QA Log'!L:L,"Exit Interview 2",'QA Log'!Z:Z,"Approved"),"") -> 0 | BT4: =IF(A4="","", SUM( COUNTIFS('QA Log'!D:D,A4,'QA Log'!M:M,"Vignette",'QA Log'!Z:Z,"Rejected",'QA Log'!L:L,"*Exit Interview 1*"), COUNTIFS('QA Log'!D:D,A4,'QA Log'!M:M,"Vignette",'QA Log'!Z:Z,"Rejected",'QA Log'!L:L,"*Exit Interview 2*") ) ) -> 0 | BU4: =IF(A4<>"",BO4-BQ4,"") -> 2 | BV4: =IF(A4<>"",SUM(BO4,BD4,AU4,AM4,AD4,T4,I4),"") -> #NAME? | BW4: =IF(A4<>"",SUM(BP4,BE4,AV4,AN4,AE4,U4,J4),"") -> 23 | BX4: =IF(A4<>"",SUM(BQ4,BF4,AW4,AO4,AF4,V4,K4),"") -> 8 | BY4: =IF(A4<>"",SUM(BT4,BM4,BB4,AS4,AK4,AB4,R4),"") -> 0 | BZ4: =IF(A4<>"",BV4-BX4,"") -> #NAME? | CA4: =IF( A4="","", IF( OR(D4="RH",D4="PH",D4="SHC"), "Not Applicable", IF(AND(I4<=J4,T4<=U4),"Fully Received","Not Received") ) ) -> #NAME? | CB4: =IF(A4<>"", IF(OR(D4="DH",D4="CHC",D4="BHC"),"Not Applicable",IF(AND(AD4<=AE4,AM4<=AN4),"Fully Received","Not Received")),"") -> #NAME? | CC4: =IF(A4<>"",IF(AND(AU4<=AV4,BD4<=BE4,BO4<=BP4),"Fully Received","Not Received"),"") -> Fully Received | CD4: =IF( A4="","", IF( OR(D4="RH",D4="PH",D4="SHC"), "Not Applicable", IF(AND(I4<=K4,T4<=V4),"Fully Received","Not Received") ) ) -> #NAME? | CE4: =IF(A4<>"",IF(OR(D4="DH",D4="CHC",D4="BHC"),"Not Applicable",IF(AND(AD4<=AF4,AM4<=AO4),"Fully Received","Not Received")),"") -> #NAME? | CF4: =IF(A4<>"",IF(AND(AU4<=AW4,BD4<=BF4,BO4<=BQ4),"Fully Received","Not Received"),"") -> Not Received | CG4: =IF(A4<>"",IF(AND(CD4="Fully Received", CE4="Fully Received", CF4="Fully Received"),"Completed Based on Data",IF(AND(CD4="Not Received", CE4="Not Received", CF4="Not Received"),"Not Completed Based on Data","Partially Completed")),"") -> #NAME?
